Workbook

Sheet Podatki
A1: Združen seznam 72 težav iz prvega kroga z ocenami resnosti treh ocenjevalcev iz drugega kroga.
A3: Št. | B3: Prototip | C3: Orodje | D3: Zaslon | E3: Naslov težave | F3: Opis težave | G3: Mesto oziroma element | H3: Hevristika | I3: Ocenjevalec 1 | J3: Ocenjevalec 2 | K3: Ocenjevalec 3 | L3: Povprečna resnost | M3: Popolna | N3: Rang Ocenjevalec1 | O3: Rang Ocenjevalec 2 | P3: Rang Ocenjevalec 3 | Q3: Vsota rangov
A4: 1 | B4: A | C4: Visily | D4: 1, 2, 4, 5 | E4: Navigacijska vrstica navaja igro v teku | F4: Navigacijska vrstica na vrhu strani navaja pot Domača stran, Beseda, Igra v teku, na teh zaslonih pa igra ni začeta ali je že končana. Na zaslonu 2 je v zgornjem delu tudi gumb Nazaj na igro, na isti strani pa so gumbi za začetek igre. | G4: Navigacijska vrstica na vrhu strani, gumb Nazaj na igro | H4: 1 | I4: 3 | J4: 4 | K4: 2 | L4: =AVERAGE(I4:K4) -> 3 | M4: =IF(COUNT(I4:K4)=3,1,0) -> 1 | N4: =IF($M4=0,"",COUNTIFS($B$4:$B$75,$B4,$M$4:$M$75,1,I$4:I$75,"<"&I4)+(COUNTIFS($B$4:$B$75,$B4,$M$4:$M$75,1,I$4:I$75,I4)+1)/2) -> 12 | O4: =IF($M4=0,"",COUNTIFS($B$4:$B$75,$B4,$M$4:$M$75,1,J$4:J$75,"<"&J4)+(COUNTIFS($B$4:$B$75,$B4,$M$4:$M$75,1,J$4:J$75,J4)+1)/2) -> 19.5 | P4: =IF($M4=0,"",COUNTIFS($B$4:$B$75,$B4,$M$4:$M$75,1,K$4:K$75,"<"&K4)+(COUNTIFS($B$4:$B$75,$B4,$M$4:$M$75,1,K$4:K$75,K4)+1)/2) -> 13 | Q4: =IF($M4=0,0,N4+O4+P4) -> 44.5
A5: 2 | B5: A | C5: Visily | D5: 1, 7 | E5: Predogledne grafike iger se razlikujejo od videza iger | F5: Grafike v polju z dnevnimi izzivi na zaslonu 1 in v polju z drugimi današnjimi igrami na zaslonu 7 prikazujejo igre drugače, kot so prikazane na igralnih zaslonih. | G5: Predogledne grafike iger | H5: 2 | I5: 2 | J5: 3 | K5: 1 | L5: =AVERAGE(I5:K5) -> 2 | M5: =IF(COUNT(I5:K5)=3,1,0) -> 1 | N5: =IF($M5=0,"",COUNTIFS($B$4:$B$75,$B5,$M$4:$M$75,1,I$4:I$75,"<"&I5)+(COUNTIFS($B$4:$B$75,$B5,$M$4:$M$75,1,I$4:I$75,I5)+1)/2) -> 5.5 | O5: =IF($M5=0,"",COUNTIFS($B$4:$B$75,$B5,$M$4:$M$75,1,J$4:J$75,"<"&J5)+(COUNTIFS($B$4:$B$75,$B5,$M$4:$M$75,1,J$4:J$75,J5)+1)/2) -> 13 | P5: =IF($M5=0,"",COUNTIFS($B$4:$B$75,$B5,$M$4:$M$75,1,K$4:K$75,"<"&K5)+(COUNTIFS($B$4:$B$75,$B5,$M$4:$M$75,1,K$4:K$75,K5)+1)/2) -> 6 | Q5: =IF($M5=0,0,N5+O5+P5) -> 24.5
A6: 3 | B6: A | C6: Visily | D6: 1 | E6: Vsebina na domačem zaslonu ni razvrščena po pomembnosti | F6: Na zaslonu so elementi prikazani brez vidnega poudarka na eni vsebini pred drugo. | G6: Celoten zaslon | H6: 8 | I6: 1 | J6: 3 | K6: 0 | L6: =AVERAGE(I6:K6) -> 1.3333333 | M6: =IF(COUNT(I6:K6)=3,1,0) -> 1 | N6: =IF($M6=0,"",COUNTIFS($B$4:$B$75,$B6,$M$4:$M$75,1,I$4:I$75,"<"&I6)+(COUNTIFS($B$4:$B$75,$B6,$M$4:$M$75,1,I$4:I$75,I6)+1)/2) -> 1.5 | O6: =IF($M6=0,"",COUNTIFS($B$4:$B$75,$B6,$M$4:$M$75,1,J$4:J$75,"<"&J6)+(COUNTIFS($B$4:$B$75,$B6,$M$4:$M$75,1,J$4:J$75,J6)+1)/2) -> 13 | P6: =IF($M6=0,"",COUNTIFS($B$4:$B$75,$B6,$M$4:$M$75,1,K$4:K$75,"<"&K6)+(COUNTIFS($B$4:$B$75,$B6,$M$4:$M$75,1,K$4:K$75,K6)+1)/2) -> 1.5 | Q6: =IF($M6=0,0,N6+O6+P6) -> 16
A7: 4 | B7: A | C7: Visily | D7: 2 | E7: Manjkajoča presledka v primeru ugiba | F7: V polju s primerom ugiba za vejico in pred črko L ni presledka. | G7: Polje s primerom ugiba | H7: 2 | I7: 1 | J7: 3 | K7: 1 | L7: =AVERAGE(I7:K7) -> 1.6666667 | M7: =IF(COUNT(I7:K7)=3,1,0) -> 1 | N7: =IF($M7=0,"",COUNTIFS($B$4:$B$75,$B7,$M$4:$M$75,1,I$4:I$75,"<"&I7)+(COUNTIFS($B$4:$B$75,$B7,$M$4:$M$75,1,I$4:I$75,I7)+1)/2) -> 1.5 | O7: =IF($M7=0,"",COUNTIFS($B$4:$B$75,$B7,$M$4:$M$75,1,J$4:J$75,"<"&J7)+(COUNTIFS($B$4:$B$75,$B7,$M$4:$M$75,1,J$4:J$75,J7)+1)/2) -> 13 | P7: =IF($M7=0,"",COUNTIFS($B$4:$B$75,$B7,$M$4:$M$75,1,K$4:K$75,"<"&K7)+(COUNTIFS($B$4:$B$75,$B7,$M$4:$M$75,1,K$4:K$75,K7)+1)/2) -> 6 | Q7: =IF($M7=0,0,N7+O7+P7) -> 20.5
A8: 5 | B8: A | C8: Visily | D8: 2 | E8: Dve različni oznaki za začetek igre | F8: Na zaslonu sta gumb Začni z igro v polju Namig dneva in gumb Igraj Beseda v spodnjem delu strani. | G8: Gumb Začni z igro, gumb Igraj Beseda | H8: 4 | I8: 3 | J8: 2 | K8: 0 | L8: =AVERAGE(I8:K8) -> 1.6666667 | M8: =IF(COUNT(I8:K8)=3,1,0) -> 1 | N8: =IF($M8=0,"",COUNTIFS($B$4:$B$75,$B8,$M$4:$M$75,1,I$4:I$75,"<"&I8)+(COUNTIFS($B$4:$B$75,$B8,$M$4:$M$75,1,I$4:I$75,I8)+1)/2) -> 12 | O8: =IF($M8=0,"",COUNTIFS($B$4:$B$75,$B8,$M$4:$M$75,1,J$4:J$75,"<"&J8)+(COUNTIFS($B$4:$B$75,$B8,$M$4:$M$75,1,J$4:J$75,J8)+1)/2) -> 5.5 | P8: =IF($M8=0,"",COUNTIFS($B$4:$B$75,$B8,$M$4:$M$75,1,K$4:K$75,"<"&K8)+(COUNTIFS($B$4:$B$75,$B8,$M$4:$M$75,1,K$4:K$75,K8)+1)/2) -> 1.5 | Q8: =IF($M8=0,0,N8+O8+P8) -> 19
A9: 6 | B9: A | C9: Visily | D9: 3 | E9: Slog besedila v razdelku Kako igrati se razlikuje od besedila pravil | F9: Besedilo v stranskem razdelku Kako igrati je formulirano drugače kot besedilo celotnih pravil igre. | G9: Razdelek Kako igrati v levem stolpcu | H9: 2 | I9: 2 | J9: 2 | K9: 1 | L9: =AVERAGE(I9:K9) -> 1.6666667 | M9: =IF(COUNT(I9:K9)=3,1,0) -> 1 | N9: =IF($M9=0,"",COUNTIFS($B$4:$B$75,$B9,$M$4:$M$75,1,I$4:I$75,"<"&I9)+(COUNTIFS($B$4:$B$75,$B9,$M$4:$M$75,1,I$4:I$75,I9)+1)/2) -> 5.5 | O9: =IF($M9=0,"",COUNTIFS($B$4:$B$75,$B9,$M$4:$M$75,1,J$4:J$75,"<"&J9)+(COUNTIFS($B$4:$B$75,$B9,$M$4:$M$75,1,J$4:J$75,J9)+1)/2) -> 5.5 | P9: =IF($M9=0,"",COUNTIFS($B$4:$B$75,$B9,$M$4:$M$75,1,K$4:K$75,"<"&K9)+(COUNTIFS($B$4:$B$75,$B9,$M$4:$M$75,1,K$4:K$75,K9)+1)/2) -> 6 | Q9: =IF($M9=0,0,N9+O9+P9) -> 17
A10: 7 | B10: A | C10: Visily | D10: 3, 6 | E10: Noge strani ni | F10: Na zaslonih 3 in 6 v spodnjem delu strani ni noge. | G10: Spodnji del strani | H10: 4 | I10: 4 | J10: 2 | K10: 3 | L10: =AVERAGE(I10:K10) -> 3 | M10: =IF(COUNT(I10:K10)=3,1,0) -> 1 | N10: =IF($M10=0,"",COUNTIFS($B$4:$B$75,$B10,$M$4:$M$75,1,I$4:I$75,"<"&I10)+(COUNTIFS($B$4:$B$75,$B10,$M$4:$M$75,1,I$4:I$75,I10)+1)/2) -> 18.5 | O10: =IF($M10=0,"",COUNTIFS($B$4:$B$75,$B10,$M$4:$M$75,1,J$4:J$75,"<"&J10)+(COUNTIFS($B$4:$B$75,$B10,$M$4:$M$75,1,J$4:J$75,J10)+1)/2) -> 5.5 | P10: =IF($M10=0,"",COUNTIFS($B$4:$B$75,$B10,$M$4:$M$75,1,K$4:K$75,"<"&K10)+(COUNTIFS($B$4:$B$75,$B10,$M$4:$M$75,1,K$4:K$75,K10)+1)/2) -> 18 | Q10: =IF($M10=0,0,N10+O10+P10) -> 42
A11: 8 | B11: A | C11: Visily | D11: 3 | E11: Gumb Oddaj ugib je prikazan v aktivni barvi pri prazni mreži | F11: Mreža za vnos besede je prazna, gumb Oddaj ugib pod tipkovnico pa je prikazan v polni barvi. | G11: Gumb Oddaj ugib pod tipkovnico | H11: 5 | I11: 3 | J11: 2 | K11: 2 | L11: =AVERAGE(I11:K11) -> 2.3333333 | M11: =IF(COUNT(I11:K11)=3,1,0) -> 1 | N11: =IF($M11=0,"",COUNTIFS($B$4:$B$75,$B11,$M$4:$M$75,1,I$4:I$75,"<"&I11)+(COUNTIFS($B$4:$B$75,$B11,$M$4:$M$75,1,I$4:I$75,I11)+1)/2) -> 12 | O11: =IF($M11=0,"",COUNTIFS($B$4:$B$75,$B11,$M$4:$M$75,1,J$4:J$75,"<"&J11)+(COUNTIFS($B$4:$B$75,$B11,$M$4:$M$75,1,J$4:J$75,J11)+1)/2) -> 5.5 | P11: =IF($M11=0,"",COUNTIFS($B$4:$B$75,$B11,$M$4:$M$75,1,K$4:K$75,"<"&K11)+(COUNTIFS($B$4:$B$75,$B11,$M$4:$M$75,1,K$4:K$75,K11)+1)/2) -> 13 | Q11: =IF($M11=0,0,N11+O11+P11) -> 30.5
A12: 9 | B12: A | C12: Visily | D12: 3 | E12: Ozek stolpec besedila v razdelku Kako igrati | F12: Razdelek Kako igrati je postavljen v ozek stolpec, besedilo v njem se lomi v kratke vrstice. | G12: Razdelek Kako igrati | H12: 8 | I12: 2 | J12: 3 | K12: 1 | L12: =AVERAGE(I12:K12) -> 2 | M12: =IF(COUNT(I12:K12)=3,1,0) -> 1 | N12: =IF($M12=0,"",COUNTIFS($B$4:$B$75,$B12,$M$4:$M$75,1,I$4:I$75,"<"&I12)+(COUNTIFS($B$4:$B$75,$B12,$M$4:$M$75,1,I$4:I$75,I12)+1)/2) -> 5.5 | O12: =IF($M12=0,"",COUNTIFS($B$4:$B$75,$B12,$M$4:$M$75,1,J$4:J$75,"<"&J12)+(COUNTIFS($B$4:$B$75,$B12,$M$4:$M$75,1,J$4:J$75,J12)+1)/2) -> 13 | P12: =IF($M12=0,"",COUNTIFS($B$4:$B$75,$B12,$M$4:$M$75,1,K$4:K$75,"<"&K12)+(COUNTIFS($B$4:$B$75,$B12,$M$4:$M$75,1,K$4:K$75,K12)+1)/2) -> 6 | Q12: =IF($M12=0,0,N12+O12+P12) -> 24.5
A13: 10 | B13: A | C13: Visily | D13: 3 | E13: Razdelka z dosežki in obvestilom o posodobitvi med igro | F13: V desnem stranskem stolpcu sta med igro prikazana razdelka Današnji dosežki in Nova posodobitev. | G13: Desni stranski stolpec | H13: 8 | I13: 2 | J13: 2 | K13: 1 | L13: =AVERAGE(I13:K13) -> 1.6666667 | M13: =IF(COUNT(I13:K13)=3,1,0) -> 1 | N13: =IF($M13=0,"",COUNTIFS($B$4:$B$75,$B13,$M$4:$M$75,1,I$4:I$75,"<"&I13)+(COUNTIFS($B$4:$B$75,$B13,$M$4:$M$75,1,I$4:I$75,I13)+1)/2) -> 5.5 | O13: =IF($M13=0,"",COUNTIFS($B$4:$B$75,$B13,$M$4:$M$75,1,J$4:J$75,"<"&J13)+(COUNTIFS($B$4:$B$75,$B13,$M$4:$M$75,1,J$4:J$75,J13)+1)/2) -> 5.5 | P13: =IF($M13=0,"",COUNTIFS($B$4:$B$75,$B13,$M$4:$M$75,1,K$4:K$75,"<"&K13)+(COUNTIFS($B$4:$B$75,$B13,$M$4:$M$75,1,K$4:K$75,K13)+1)/2) -> 6 | Q13: =IF($M13=0,0,N13+O13+P13) -> 17
A14: 11 | B14: A | C14: Visily | D14: 4 | E14: Oznaka Neveljaven vnos je ločena od sporočila o napaki | F14: Oznaka Neveljaven vnos je majhna in postavljena v zgornji desni kot, kartica z razlago napake je na sredini zaslona. | G14: Oznaka Neveljaven vnos zgoraj desno | H14: 1 | I14: 4 | J14: 4 | K14: 2 | L14: =AVERAGE(I14:K14) -> 3.3333333 | M14: =IF(COUNT(I14:K14)=3,1,0) -> 1 | N14: =IF($M14=0,"",COUNTIFS($B$4:$B$75,$B14,$M$4:$M$75,1,I$4:I$75,"<"&I14)+(COUNTIFS($B$4:$B$75,$B14,$M$4:$M$75,1,I$4:I$75,I14)+1)/2) -> 18.5 | O14: =IF($M14=0,"",COUNTIFS($B$4:$B$75,$B14,$M$4:$M$75,1,J$4:J$75,"<"&J14)+(COUNTIFS($B$4:$B$75,$B14,$M$4:$M$75,1,J$4:J$75,J14)+1)/2) -> 19.5 | P14: =IF($M14=0,"",COUNTIFS($B$4:$B$75,$B14,$M$4:$M$75,1,K$4:K$75,"<"&K14)+(COUNTIFS($B$4:$B$75,$B14,$M$4:$M$75,1,K$4:K$75,K14)+1)/2) -> 13 | Q14: =IF($M14=0,0,N14+O14+P14) -> 51
A15: 12 | B15: A | C15: Visily | D15: 4, 7 | E15: Ilustraciji vsebujeta angleško besedilo | F15: Ilustracija nad sporočilom o napaki prikazuje ploščice z napisom WHY?, ilustracija ob naslovu Dnevna križanka pa napisa START in SPACE. Slog ploščic na ilustraciji se razlikuje od ploščic v igri. | G15: Ilustracija nad sporočilom o napaki, ilustracija zgoraj desno | H15: 2 | I15: 2 | J15: 3 | K15: 2 | L15: =AVERAGE(I15:K15) -> 2.3333333 | M15: =IF(COUNT(I15:K15)=3,1,0) -> 1 | N15: =IF($M15=0,"",COUNTIFS($B$4:$B$75,$B15,$M$4:$M$75,1,I$4:I$75,"<"&I15)+(COUNTIFS($B$4:$B$75,$B15,$M$4:$M$75,1,I$4:I$75,I15)+1)/2) -> 5.5 | O15: =IF($M15=0,"",COUNTIFS($B$4:$B$75,$B15,$M$4:$M$75,1,J$4:J$75,"<"&J15)+(COUNTIFS($B$4:$B$75,$B15,$M$4:$M$75,1,J$4:J$75,J15)+1)/2) -> 13 | P15: =IF($M15=0,"",COUNTIFS($B$4:$B$75,$B15,$M$4:$M$75,1,K$4:K$75,"<"&K15)+(COUNTIFS($B$4:$B$75,$B15,$M$4:$M$75,1,K$4:K$75,K15)+1)/2) -> 13 | Q15: =IF($M15=0,0,N15+O15+P15) -> 31.5
... A75: 72 | B75: D | C75: Figma Make | D75: 7 | E75: Gumba za pomoč ali navodila v navigacijskem predelu ni | F75: V navigacijskem predelu zaslona križanke ni gumba za pomoč ali navodila. | G75: Navigacijski predel | H75: 10 | I75: 4 | J75: 4 | K75: 4 | L75: =AVERAGE(I75:K75) -> 4 | M75: =IF(COUNT(I75:K75)=3,1,0) -> 1 | N75: =IF($M75=0,"",COUNTIFS($B$4:$B$75,$B75,$M$4:$M$75,1,I$4:I$75,"<"&I75)+(COUNTIFS($B$4:$B$75,$B75,$M$4:$M$75,1,I$4:I$75,I75)+1)/2) -> 7.5 | O75: =IF($M75=0,"",COUNTIFS($B$4:$B$75,$B75,$M$4:$M$75,1,J$4:J$75,"<"&J75)+(COUNTIFS($B$4:$B$75,$B75,$M$4:$M$75,1,J$4:J$75,J75)+1)/2) -> 7.5 | P75: =IF($M75=0,"",COUNTIFS($B$4:$B$75,$B75,$M$4:$M$75,1,K$4:K$75,"<"&K75)+(COUNTIFS($B$4:$B$75,$B75,$M$4:$M$75,1,K$4:K$75,K75)+1)/2) -> 8 | Q75: =IF($M75=0,0,N75+O75+P75) -> 23

Sheet Analiza
A1: Ocena hevristike je najvišja povprečna resnost med težavami, ki so ji pripisane. Skupna ocena prototipa je vsota ocen po osmih ocenljivih hevristikah. Hevristiki 5 in 7 sta izključeni iz izračuna.
A3: Ocene po hevristikah
A4: Št. | B4: Hevristika | C4: A – Visily | D4: B – Ročni | E4: C – Uizard | F4: D – Figma Make
A5: 1 | B5: Vidnost stanja sistema | C5: =IF(COUNTIFS(Podatki!$B$4:$B$75,"A",Podatki!$H$4:$H$75,1)=0,0,_xlfn.MAXIFS(Podatki!$L$4:$L$75,Podatki!$B$4:$B$75,"A",Podatki!$H$4:$H$75,1)) -> 3.3333333 | D5: =IF(COUNTIFS(Podatki!$B$4:$B$75,"B",Podatki!$H$4:$H$75,1)=0,0,_xlfn.MAXIFS(Podatki!$L$4:$L$75,Podatki!$B$4:$B$75,"B",Podatki!$H$4:$H$75,1)) -> 3 | E5: =IF(COUNTIFS(Podatki!$B$4:$B$75,"C",Podatki!$H$4:$H$75,1)=0,0,_xlfn.MAXIFS(Podatki!$L$4:$L$75,Podatki!$B$4:$B$75,"C",Podatki!$H$4:$H$75,1)) -> 3.6666667 | F5: =IF(COUNTIFS(Podatki!$B$4:$B$75,"D",Podatki!$H$4:$H$75,1)=0,0,_xlfn.MAXIFS(Podatki!$L$4:$L$75,Podatki!$B$4:$B$75,"D",Podatki!$H$4:$H$75,1)) -> 3.3333333
A6: 2 | B6: Ujemanje sistema z resničnim svetom | C6: =IF(COUNTIFS(Podatki!$B$4:$B$75,"A",Podatki!$H$4:$H$75,2)=0,0,_xlfn.MAXIFS(Podatki!$L$4:$L$75,Podatki!$B$4:$B$75,"A",Podatki!$H$4:$H$75,2)) -> 2.3333333 | D6: =IF(COUNTIFS(Podatki!$B$4:$B$75,"B",Podatki!$H$4:$H$75,2)=0,0,_xlfn.MAXIFS(Podatki!$L$4:$L$75,Podatki!$B$4:$B$75,"B",Podatki!$H$4:$H$75,2)) -> 3.3333333 | E6: =IF(COUNTIFS(Podatki!$B$4:$B$75,"C",Podatki!$H$4:$H$75,2)=0,0,_xlfn.MAXIFS(Podatki!$L$4:$L$75,Podatki!$B$4:$B$75,"C",Podatki!$H$4:$H$75,2)) -> 3.6666667 | F6: =IF(COUNTIFS(Podatki!$B$4:$B$75,"D",Podatki!$H$4:$H$75,2)=0,0,_xlfn.MAXIFS(Podatki!$L$4:$L$75,Podatki!$B$4:$B$75,"D",Podatki!$H$4:$H$75,2)) -> 2
A7: 3 | B7: Nadzor in svoboda uporabnika | C7: =IF(COUNTIFS(Podatki!$B$4:$B$75,"A",Podatki!$H$4:$H$75,3)=0,0,_xlfn.MAXIFS(Podatki!$L$4:$L$75,Podatki!$B$4:$B$75,"A",Podatki!$H$4:$H$75,3)) -> 3.6666667 | D7: =IF(COUNTIFS(Podatki!$B$4:$B$75,"B",Podatki!$H$4:$H$75,3)=0,0,_xlfn.MAXIFS(Podatki!$L$4:$L$75,Podatki!$B$4:$B$75,"B",Podatki!$H$4:$H$75,3)) -> 0 | E7: =IF(COUNTIFS(Podatki!$B$4:$B$75,"C",Podatki!$H$4:$H$75,3)=0,0,_xlfn.MAXIFS(Podatki!$L$4:$L$75,Podatki!$B$4:$B$75,"C",Podatki!$H$4:$H$75,3)) -> 4 | F7: =IF(COUNTIFS(Podatki!$B$4:$B$75,"D",Podatki!$H$4:$H$75,3)=0,0,_xlfn.MAXIFS(Podatki!$L$4:$L$75,Podatki!$B$4:$B$75,"D",Podatki!$H$4:$H$75,3)) -> 0
A8: 4 | B8: Konsistentnost in standardi | C8: =IF(COUNTIFS(Podatki!$B$4:$B$75,"A",Podatki!$H$4:$H$75,4)=0,0,_xlfn.MAXIFS(Podatki!$L$4:$L$75,Podatki!$B$4:$B$75,"A",Podatki!$H$4:$H$75,4)) -> 3.6666667 | D8: =IF(COUNTIFS(Podatki!$B$4:$B$75,"B",Podatki!$H$4:$H$75,4)=0,0,_xlfn.MAXIFS(Podatki!$L$4:$L$75,Podatki!$B$4:$B$75,"B",Podatki!$H$4:$H$75,4)) -> 1.3333333 | E8: =IF(COUNTIFS(Podatki!$B$4:$B$75,"C",Podatki!$H$4:$H$75,4)=0,0,_xlfn.MAXIFS(Podatki!$L$4:$L$75,Podatki!$B$4:$B$75,"C",Podatki!$H$4:$H$75,4)) -> 3.6666667 | F8: =IF(COUNTIFS(Podatki!$B$4:$B$75,"D",Podatki!$H$4:$H$75,4)=0,0,_xlfn.MAXIFS(Podatki!$L$4:$L$75,Podatki!$B$4:$B$75,"D",Podatki!$H$4:$H$75,4)) -> 3.6666667
A9: 5 | B9: Preprečevanje napak | C9: =IF(COUNTIFS(Podatki!$B$4:$B$75,"A",Podatki!$H$4:$H$75,5)=0,0,_xlfn.MAXIFS(Podatki!$L$4:$L$75,Podatki!$B$4:$B$75,"A",Podatki!$H$4:$H$75,5)) -> 2.3333333 | D9: =IF(COUNTIFS(Podatki!$B$4:$B$75,"B",Podatki!$H$4:$H$75,5)=0,0,_xlfn.MAXIFS(Podatki!$L$4:$L$75,Podatki!$B$4:$B$75,"B",Podatki!$H$4:$H$75,5)) -> 0 | E9: =IF(COUNTIFS(Podatki!$B$4:$B$75,"C",Podatki!$H$4:$H$75,5)=0,0,_xlfn.MAXIFS(Podatki!$L$4:$L$75,Podatki!$B$4:$B$75,"C",Podatki!$H$4:$H$75,5)) -> 0 | F9: =IF(COUNTIFS(Podatki!$B$4:$B$75,"D",Podatki!$H$4:$H$75,5)=0,0,_xlfn.MAXIFS(Podatki!$L$4:$L$75,Podatki!$B$4:$B$75,"D",Podatki!$H$4:$H$75,5)) -> 0
A10: 6 | B10: Prepoznavanje namesto pomnjenja | C10: =IF(COUNTIFS(Podatki!$B$4:$B$75,"A",Podatki!$H$4:$H$75,6)=0,0,_xlfn.MAXIFS(Podatki!$L$4:$L$75,Podatki!$B$4:$B$75,"A",Podatki!$H$4:$H$75,6)) -> 3 | D10: =IF(COUNTIFS(Podatki!$B$4:$B$75,"B",Podatki!$H$4:$H$75,6)=0,0,_xlfn.MAXIFS(Podatki!$L$4:$L$75,Podatki!$B$4:$B$75,"B",Podatki!$H$4:$H$75,6)) -> 3 | E10: =IF(COUNTIFS(Podatki!$B$4:$B$75,"C",Podatki!$H$4:$H$75,6)=0,0,_xlfn.MAXIFS(Podatki!$L$4:$L$75,Podatki!$B$4:$B$75,"C",Podatki!$H$4:$H$75,6)) -> 0 | F10: =IF(COUNTIFS(Podatki!$B$4:$B$75,"D",Podatki!$H$4:$H$75,6)=0,0,_xlfn.MAXIFS(Podatki!$L$4:$L$75,Podatki!$B$4:$B$75,"D",Podatki!$H$4:$H$75,6)) -> 0
A11: 7 | B11: Prilagodljivost in učinkovitost uporabe | C11: =IF(COUNTIFS(Podatki!$B$4:$B$75,"A",Podatki!$H$4:$H$75,7)=0,0,_xlfn.MAXIFS(Podatki!$L$4:$L$75,Podatki!$B$4:$B$75,"A",Podatki!$H$4:$H$75,7)) -> 0 | D11: =IF(COUNTIFS(Podatki!$B$4:$B$75,"B",Podatki!$H$4:$H$75,7)=0,0,_xlfn.MAXIFS(Podatki!$L$4:$L$75,Podatki!$B$4:$B$75,"B",Podatki!$H$4:$H$75,7)) -> 0 | E11: =IF(COUNTIFS(Podatki!$B$4:$B$75,"C",Podatki!$H$4:$H$75,7)=0,0,_xlfn.MAXIFS(Podatki!$L$4:$L$75,Podatki!$B$4:$B$75,"C",Podatki!$H$4:$H$75,7)) -> 0 | F11: =IF(COUNTIFS(Podatki!$B$4:$B$75,"D",Podatki!$H$4:$H$75,7)=0,0,_xlfn.MAXIFS(Podatki!$L$4:$L$75,Podatki!$B$4:$B$75,"D",Podatki!$H$4:$H$75,7)) -> 0
A12: 8 | B12: Estetsko in minimalistično oblikovanje | C12: =IF(COUNTIFS(Podatki!$B$4:$B$75,"A",Podatki!$H$4:$H$75,8)=0,0,_xlfn.MAXIFS(Podatki!$L$4:$L$75,Podatki!$B$4:$B$75,"A",Podatki!$H$4:$H$75,8)) -> 2.3333333 | D12: =IF(COUNTIFS(Podatki!$B$4:$B$75,"B",Podatki!$H$4:$H$75,8)=0,0,_xlfn.MAXIFS(Podatki!$L$4:$L$75,Podatki!$B$4:$B$75,"B",Podatki!$H$4:$H$75,8)) -> 0 | E12: =IF(COUNTIFS(Podatki!$B$4:$B$75,"C",Podatki!$H$4:$H$75,8)=0,0,_xlfn.MAXIFS(Podatki!$L$4:$L$75,Podatki!$B$4:$B$75,"C",Podatki!$H$4:$H$75,8)) -> 4 | F12: =IF(COUNTIFS(Podatki!$B$4:$B$75,"D",Podatki!$H$4:$H$75,8)=0,0,_xlfn.MAXIFS(Podatki!$L$4:$L$75,Podatki!$B$4:$B$75,"D",Podatki!$H$4:$H$75,8)) -> 0
A13: 9 | B13: Pomoč pri prepoznavanju in odpravljanju napak | C13: =IF(COUNTIFS(Podatki!$B$4:$B$75,"A",Podatki!$H$4:$H$75,9)=0,0,_xlfn.MAXIFS(Podatki!$L$4:$L$75,Podatki!$B$4:$B$75,"A",Podatki!$H$4:$H$75,9)) -> 0 | D13: =IF(COUNTIFS(Podatki!$B$4:$B$75,"B",Podatki!$H$4:$H$75,9)=0,0,_xlfn.MAXIFS(Podatki!$L$4:$L$75,Podatki!$B$4:$B$75,"B",Podatki!$H$4:$H$75,9)) -> 0 | E13: =IF(COUNTIFS(Podatki!$B$4:$B$75,"C",Podatki!$H$4:$H$75,9)=0,0,_xlfn.MAXIFS(Podatki!$L$4:$L$75,Podatki!$B$4:$B$75,"C",Podatki!$H$4:$H$75,9)) -> 0 | F13: =IF(COUNTIFS(Podatki!$B$4:$B$75,"D",Podatki!$H$4:$H$75,9)=0,0,_xlfn.MAXIFS(Podatki!$L$4:$L$75,Podatki!$B$4:$B$75,"D",Podatki!$H$4:$H$75,9)) -> 0
A14: 10 | B14: Pomoč in dokumentacija | C14: =IF(COUNTIFS(Podatki!$B$4:$B$75,"A",Podatki!$H$4:$H$75,10)=0,0,_xlfn.MAXIFS(Podatki!$L$4:$L$75,Podatki!$B$4:$B$75,"A",Podatki!$H$4:$H$75,10)) -> 0 | D14: =IF(COUNTIFS(Podatki!$B$4:$B$75,"B",Podatki!$H$4:$H$75,10)=0,0,_xlfn.MAXIFS(Podatki!$L$4:$L$75,Podatki!$B$4:$B$75,"B",Podatki!$H$4:$H$75,10)) -> 3 | E14: =IF(COUNTIFS(Podatki!$B$4:$B$75,"C",Podatki!$H$4:$H$75,10)=0,0,_xlfn.MAXIFS(Podatki!$L$4:$L$75,Podatki!$B$4:$B$75,"C",Podatki!$H$4:$H$75,10)) -> 2.3333333 | F14: =IF(COUNTIFS(Podatki!$B$4:$B$75,"D",Podatki!$H$4:$H$75,10)=0,0,_xlfn.MAXIFS(Podatki!$L$4:$L$75,Podatki!$B$4:$B$75,"D",Podatki!$H$4:$H$75,10)) -> 4
B15: Skupna ocena prototipa | C15: =SUM(C5:C14)-C9-C11 -> 18.333333 | D15: =SUM(D5:D14)-D9-D11 -> 13.666667 | E15: =SUM(E5:E14)-E9-E11 -> 21.333333 | F15: =SUM(F5:F14)-F9-F11 -> 13
B16: Največja možna ocena | C16: 32 | D16: 32 | E16: 32 | F16: 32
A18: Število evidentiranih težav po hevristikah
A19: Št. | B19: Hevristika | C19: A – Visily | D19: B – Ročni | E19: C – Uizard | F19: D – Figma Make | G19: Skupaj
A20: 1 | B20: Vidnost stanja sistema | C20: =COUNTIFS(Podatki!$B$4:$B$75,"A",Podatki!$H$4:$H$75,1) -> 3 | D20: =COUNTIFS(Podatki!$B$4:$B$75,"B",Podatki!$H$4:$H$75,1) -> 1 | E20: =COUNTIFS(Podatki!$B$4:$B$75,"C",Podatki!$H$4:$H$75,1) -> 10 | F20: =COUNTIFS(Podatki!$B$4:$B$75,"D",Podatki!$H$4:$H$75,1) -> 2 | G20: =SUM(C20:F20) -> 16
A21: 2 | B21: Ujemanje sistema z resničnim svetom | C21: =COUNTIFS(Podatki!$B$4:$B$75,"A",Podatki!$H$4:$H$75,2) -> 4 | D21: =COUNTIFS(Podatki!$B$4:$B$75,"B",Podatki!$H$4:$H$75,2) -> 1 | E21: =COUNTIFS(Podatki!$B$4:$B$75,"C",Podatki!$H$4:$H$75,2) -> 7 | F21: =COUNTIFS(Podatki!$B$4:$B$75,"D",Podatki!$H$4:$H$75,2) -> 1 | G21: =SUM(C21:F21) -> 13
A22: 3 | B22: Nadzor in svoboda uporabnika | C22: =COUNTIFS(Podatki!$B$4:$B$75,"A",Podatki!$H$4:$H$75,3) -> 2 | D22: =COUNTIFS(Podatki!$B$4:$B$75,"B",Podatki!$H$4:$H$75,3) -> 0 | E22: =COUNTIFS(Podatki!$B$4:$B$75,"C",Podatki!$H$4:$H$75,3) -> 2 | F22: =COUNTIFS(Podatki!$B$4:$B$75,"D",Podatki!$H$4:$H$75,3) -> 0 | G22: =SUM(C22:F22) -> 4
A23: 4 | B23: Konsistentnost in standardi | C23: =COUNTIFS(Podatki!$B$4:$B$75,"A",Podatki!$H$4:$H$75,4) -> 6 | D23: =COUNTIFS(Podatki!$B$4:$B$75,"B",Podatki!$H$4:$H$75,4) -> 1 | E23: =COUNTIFS(Podatki!$B$4:$B$75,"C",Podatki!$H$4:$H$75,4) -> 9 | F23: =COUNTIFS(Podatki!$B$4:$B$75,"D",Podatki!$H$4:$H$75,4) -> 5 | G23: =SUM(C23:F23) -> 21
A24: 5 | B24: Preprečevanje napak | C24: =COUNTIFS(Podatki!$B$4:$B$75,"A",Podatki!$H$4:$H$75,5) -> 1 | D24: =COUNTIFS(Podatki!$B$4:$B$75,"B",Podatki!$H$4:$H$75,5) -> 0 | E24: =COUNTIFS(Podatki!$B$4:$B$75,"C",Podatki!$H$4:$H$75,5) -> 0 | F24: =COUNTIFS(Podatki!$B$4:$B$75,"D",Podatki!$H$4:$H$75,5) -> 0 | G24: =SUM(C24:F24) -> 1
A25: 6 | B25: Prepoznavanje namesto pomnjenja | C25: =COUNTIFS(Podatki!$B$4:$B$75,"A",Podatki!$H$4:$H$75,6) -> 1 | D25: =COUNTIFS(Podatki!$B$4:$B$75,"B",Podatki!$H$4:$H$75,6) -> 2 | E25: =COUNTIFS(Podatki!$B$4:$B$75,"C",Podatki!$H$4:$H$75,6) -> 0 | F25: =COUNTIFS(Podatki!$B$4:$B$75,"D",Podatki!$H$4:$H$75,6) -> 0 | G25: =SUM(C25:F25) -> 3
A26: 7 | B26: Prilagodljivost in učinkovitost uporabe | C26: =COUNTIFS(Podatki!$B$4:$B$75,"A",Podatki!$H$4:$H$75,7) -> 0 | D26: =COUNTIFS(Podatki!$B$4:$B$75,"B",Podatki!$H$4:$H$75,7) -> 0 | E26: =COUNTIFS(Podatki!$B$4:$B$75,"C",Podatki!$H$4:$H$75,7) -> 0 | F26: =COUNTIFS(Podatki!$B$4:$B$75,"D",Podatki!$H$4:$H$75,7) -> 0 | G26: =SUM(C26:F26) -> 0
A27: 8 | B27: Estetsko in minimalistično oblikovanje | C27: =COUNTIFS(Podatki!$B$4:$B$75,"A",Podatki!$H$4:$H$75,8) -> 4 | D27: =COUNTIFS(Podatki!$B$4:$B$75,"B",Podatki!$H$4:$H$75,8) -> 0 | E27: =COUNTIFS(Podatki!$B$4:$B$75,"C",Podatki!$H$4:$H$75,8) -> 7 | F27: =COUNTIFS(Podatki!$B$4:$B$75,"D",Podatki!$H$4:$H$75,8) -> 0 | G27: =SUM(C27:F27) -> 11
A28: 9 | B28: Pomoč pri prepoznavanju in odpravljanju napak | C28: =COUNTIFS(Podatki!$B$4:$B$75,"A",Podatki!$H$4:$H$75,9) -> 0 | D28: =COUNTIFS(Podatki!$B$4:$B$75,"B",Podatki!$H$4:$H$75,9) -> 0 | E28: =COUNTIFS(Podatki!$B$4:$B$75,"C",Podatki!$H$4:$H$75,9) -> 0 | F28: =COUNTIFS(Podatki!$B$4:$B$75,"D",Podatki!$H$4:$H$75,9) -> 0 | G28: =SUM(C28:F28) -> 0
A29: 10 | B29: Pomoč in dokumentacija | C29: =COUNTIFS(Podatki!$B$4:$B$75,"A",Podatki!$H$4:$H$75,10) -> 0 | D29: =COUNTIFS(Podatki!$B$4:$B$75,"B",Podatki!$H$4:$H$75,10) -> 1 | E29: =COUNTIFS(Podatki!$B$4:$B$75,"C",Podatki!$H$4:$H$75,10) -> 1 | F29: =COUNTIFS(Podatki!$B$4:$B$75,"D",Podatki!$H$4:$H$75,10) -> 1 | G29: =SUM(C29:F29) -> 3
B30: Skupaj težav | C30: =COUNTIF(Podatki!$B$4:$B$75,"A") -> 21 | D30: =COUNTIF(Podatki!$B$4:$B$75,"B") -> 6 | E30: =COUNTIF(Podatki!$B$4:$B$75,"C") -> 36 | F30: =COUNTIF(Podatki!$B$4:$B$75,"D") -> 9 | G30: =SUM(C30:F30) -> 72
A32: Povprečna resnost težav po prototipu
A33: Kazalnik | B33: A – Visily | C33: B – Ročni | D33: C – Uizard | E33: D – Figma Make
A34: Povprečna resnost | B34: =AVERAGEIF(Podatki!$B$4:$B$75,"A",Podatki!$L$4:$L$75) -> 2.4444444 | C34: =AVERAGEIF(Podatki!$B$4:$B$75,"B",Podatki!$L$4:$L$75) -> 2.7222222 | D34: =AVERAGEIF(Podatki!$B$4:$B$75,"C",Podatki!$L$4:$L$75) -> 3.1481481 | E34: =AVERAGEIF(Podatki!$B$4:$B$75,"D",Podatki!$L$4:$L$75) -> 3.0740741
A36: H1: povprečje skupnih ocen prototipov z umetno inteligenco proti ročnemu prototipu
A37: Povprečje skupnih ocen A, C in D | C37: =AVERAGE(C15,E15,F15) -> 17.555556
A38: Skupna ocena ročnega prototipa B | C38: =D15 -> 13.666667
A39: Razlika | C39: =C37-C38 -> 3.8888889
A40: Prag (10 % od 32 točk) | C40: 3.2
A41: Razlika presega prag | C41: =IF(ABS(C39)>C40,"da","ne") -> da
A43: Skupne ocene po orodjih glede na ročni prototip
A44: Visily (A) minus ročni (B) | C44: =C15-D15 -> 4.6666667
A45: Uizard (C) minus ročni (B) | C45: =E15-D15 -> 7.6666667
...

Sheet Kendall
A1: Kendallov koeficient skladnosti W s popravkom za vezane vrednosti, ločeno po prototipih. m = 3 ocenjevalci, n = število težav v prototipu.
A2: W = 12 × S / ( m² × (n³ − n) − m × ΣT )
A4: Prototip A – Visily
A5: n (število težav) | B5: =COUNTIFS(Podatki!$B$4:$B$75,"A",Podatki!$M$4:$M$75,1) -> 21
A6: Povprečna vsota rangov | B6: =3*(B5+1)/2 -> 33
A7: S | B7: =SUMPRODUCT((Podatki!$B$4:$B$75="A")*(Podatki!$M$4:$M$75=1)*(Podatki!$Q$4:$Q$75-B6)^2) -> 3156.5
A8: Popravek za vezi, t³ − t po oceni in ocenjevalcu
A9: Ocena | B9: Ocenjevalec 1 | C9: Ocenjevalec 2 | D9: Ocenjevalec 3
A10: 0 | B10: =COUNTIFS(Podatki!$B$4:$B$75,"A",Podatki!$M$4:$M$75,1,Podatki!$I$4:$I$75,0)^3-COUNTIFS(Podatki!$B$4:$B$75,"A",Podatki!$M$4:$M$75,1,Podatki!$I$4:$I$75,0) -> 0 | C10: =COUNTIFS(Podatki!$B$4:$B$75,"A",Podatki!$M$4:$M$75,1,Podatki!$J$4:$J$75,0)^3-COUNTIFS(Podatki!$B$4:$B$75,"A",Podatki!$M$4:$M$75,1,Podatki!$J$4:$J$75,0) -> 0 | D10: =COUNTIFS(Podatki!$B$4:$B$75,"A",Podatki!$M$4:$M$75,1,Podatki!$K$4:$K$75,0)^3-COUNTIFS(Podatki!$B$4:$B$75,"A",Podatki!$M$4:$M$75,1,Podatki!$K$4:$K$75,0) -> 6
A11: 1 | B11: =COUNTIFS(Podatki!$B$4:$B$75,"A",Podatki!$M$4:$M$75,1,Podatki!$I$4:$I$75,1)^3-COUNTIFS(Podatki!$B$4:$B$75,"A",Podatki!$M$4:$M$75,1,Podatki!$I$4:$I$75,1) -> 6 | C11: =COUNTIFS(Podatki!$B$4:$B$75,"A",Podatki!$M$4:$M$75,1,Podatki!$J$4:$J$75,1)^3-COUNTIFS(Podatki!$B$4:$B$75,"A",Podatki!$M$4:$M$75,1,Podatki!$J$4:$J$75,1) -> 6 | D11: =COUNTIFS(Podatki!$B$4:$B$75,"A",Podatki!$M$4:$M$75,1,Podatki!$K$4:$K$75,1)^3-COUNTIFS(Podatki!$B$4:$B$75,"A",Podatki!$M$4:$M$75,1,Podatki!$K$4:$K$75,1) -> 336
A12: 2 | B12: =COUNTIFS(Podatki!$B$4:$B$75,"A",Podatki!$M$4:$M$75,1,Podatki!$I$4:$I$75,2)^3-COUNTIFS(Podatki!$B$4:$B$75,"A",Podatki!$M$4:$M$75,1,Podatki!$I$4:$I$75,2) -> 210 | C12: =COUNTIFS(Podatki!$B$4:$B$75,"A",Podatki!$M$4:$M$75,1,Podatki!$J$4:$J$75,2)^3-COUNTIFS(Podatki!$B$4:$B$75,"A",Podatki!$M$4:$M$75,1,Podatki!$J$4:$J$75,2) -> 210 | D12: =COUNTIFS(Podatki!$B$4:$B$75,"A",Podatki!$M$4:$M$75,1,Podatki!$K$4:$K$75,2)^3-COUNTIFS(Podatki!$B$4:$B$75,"A",Podatki!$M$4:$M$75,1,Podatki!$K$4:$K$75,2) -> 336
A13: 3 | B13: =COUNTIFS(Podatki!$B$4:$B$75,"A",Podatki!$M$4:$M$75,1,Podatki!$I$4:$I$75,3)^3-COUNTIFS(Podatki!$B$4:$B$75,"A",Podatki!$M$4:$M$75,1,Podatki!$I$4:$I$75,3) -> 336 | C13: =COUNTIFS(Podatki!$B$4:$B$75,"A",Podatki!$M$4:$M$75,1,Podatki!$J$4:$J$75,3)^3-COUNTIFS(Podatki!$B$4:$B$75,"A",Podatki!$M$4:$M$75,1,Podatki!$J$4:$J$75,3) -> 720 | D13: =COUNTIFS(Podatki!$B$4:$B$75,"A",Podatki!$M$4:$M$75,1,Podatki!$K$4:$K$75,3)^3-COUNTIFS(Podatki!$B$4:$B$75,"A",Podatki!$M$4:$M$75,1,Podatki!$K$4:$K$75,3) -> 24
A14: 4 | B14: =COUNTIFS(Podatki!$B$4:$B$75,"A",Podatki!$M$4:$M$75,1,Podatki!$I$4:$I$75,4)^3-COUNTIFS(Podatki!$B$4:$B$75,"A",Podatki!$M$4:$M$75,1,Podatki!$I$4:$I$75,4) -> 210 | C14: =COUNTIFS(Podatki!$B$4:$B$75,"A",Podatki!$M$4:$M$75,1,Podatki!$J$4:$J$75,4)^3-COUNTIFS(Podatki!$B$4:$B$75,"A",Podatki!$M$4:$M$75,1,Podatki!$J$4:$J$75,4) -> 60 | D14: =COUNTIFS(Podatki!$B$4:$B$75,"A",Podatki!$M$4:$M$75,1,Podatki!$K$4:$K$75,4)^3-COUNTIFS(Podatki!$B$4:$B$75,"A",Podatki!$M$4:$M$75,1,Podatki!$K$4:$K$75,4) -> 6
A15: ΣT | B15: =SUM(B10:D14) -> 2466
A16: W | B16: =IF(B5<2,"",12*B7/(9*(B5^3-B5)-3*B15)) -> 0.4999604
A19: Prototip B – Ročni
A20: n (število težav) | B20: =COUNTIFS(Podatki!$B$4:$B$75,"B",Podatki!$M$4:$M$75,1) -> 6
A21: Povprečna vsota rangov | B21: =3*(B20+1)/2 -> 10.5
A22: S | B22: =SUMPRODUCT((Podatki!$B$4:$B$75="B")*(Podatki!$M$4:$M$75=1)*(Podatki!$Q$4:$Q$75-B21)^2) -> 66
A23: Popravek za vezi, t³ − t po oceni in ocenjevalcu
A24: Ocena | B24: Ocenjevalec 1 | C24: Ocenjevalec 2 | D24: Ocenjevalec 3
A25: 0 | B25: =COUNTIFS(Podatki!$B$4:$B$75,"B",Podatki!$M$4:$M$75,1,Podatki!$I$4:$I$75,0)^3-COUNTIFS(Podatki!$B$4:$B$75,"B",Podatki!$M$4:$M$75,1,Podatki!$I$4:$I$75,0) -> 0 | C25: =COUNTIFS(Podatki!$B$4:$B$75,"B",Podatki!$M$4:$M$75,1,Podatki!$J$4:$J$75,0)^3-COUNTIFS(Podatki!$B$4:$B$75,"B",Podatki!$M$4:$M$75,1,Podatki!$J$4:$J$75,0) -> 0 | D25: =COUNTIFS(Podatki!$B$4:$B$75,"B",Podatki!$M$4:$M$75,1,Podatki!$K$4:$K$75,0)^3-COUNTIFS(Podatki!$B$4:$B$75,"B",Podatki!$M$4:$M$75,1,Podatki!$K$4:$K$75,0) -> 0
A26: 1 | B26: =COUNTIFS(Podatki!$B$4:$B$75,"B",Podatki!$M$4:$M$75,1,Podatki!$I$4:$I$75,1)^3-COUNTIFS(Podatki!$B$4:$B$75,"B",Podatki!$M$4:$M$75,1,Podatki!$I$4:$I$75,1) -> 0 | C26: =COUNTIFS(Podatki!$B$4:$B$75,"B",Podatki!$M$4:$M$75,1,Podatki!$J$4:$J$75,1)^3-COUNTIFS(Podatki!$B$4:$B$75,"B",Podatki!$M$4:$M$75,1,Podatki!$J$4:$J$75,1) -> 6 | D26: =COUNTIFS(Podatki!$B$4:$B$75,"B",Podatki!$M$4:$M$75,1,Podatki!$K$4:$K$75,1)^3-COUNTIFS(Podatki!$B$4:$B$75,"B",Podatki!$M$4:$M$75,1,Podatki!$K$4:$K$75,1) -> 0
A27: 2 | B27: =COUNTIFS(Podatki!$B$4:$B$75,"B",Podatki!$M$4:$M$75,1,Podatki!$I$4:$I$75,2)^3-COUNTIFS(Podatki!$B$4:$B$75,"B",Podatki!$M$4:$M$75,1,Podatki!$I$4:$I$75,2) -> 24 | C27: =COUNTIFS(Podatki!$B$4:$B$75,"B",Podatki!$M$4:$M$75,1,Podatki!$J$4:$J$75,2)^3-COUNTIFS(Podatki!$B$4:$B$75,"B",Podatki!$M$4:$M$75,1,Podatki!$J$4:$J$75,2) -> 0 | D27: =COUNTIFS(Podatki!$B$4:$B$75,"B",Podatki!$M$4:$M$75,1,Podatki!$K$4:$K$75,2)^3-COUNTIFS(Podatki!$B$4:$B$75,"B",Podatki!$M$4:$M$75,1,Podatki!$K$4:$K$75,2) -> 0
A28: 3 | B28: =COUNTIFS(Podatki!$B$4:$B$75,"B",Podatki!$M$4:$M$75,1,Podatki!$I$4:$I$75,3)^3-COUNTIFS(Podatki!$B$4:$B$75,"B",Podatki!$M$4:$M$75,1,Podatki!$I$4:$I$75,3) -> 0 | C28: =COUNTIFS(Podatki!$B$4:$B$75,"B",Podatki!$M$4:$M$75,1,Podatki!$J$4:$J$75,3)^3-COUNTIFS(Podatki!$B$4:$B$75,"B",Podatki!$M$4:$M$75,1,Podatki!$J$4:$J$75,3) -> 6 | D28: =COUNTIFS(Podatki!$B$4:$B$75,"B",Podatki!$M$4:$M$75,1,Podatki!$K$4:$K$75,3)^3-COUNTIFS(Podatki!$B$4:$B$75,"B",Podatki!$M$4:$M$75,1,Podatki!$K$4:$K$75,3) -> 0
A29: 4 | B29: =COUNTIFS(Podatki!$B$4:$B$75,"B",Podatki!$M$4:$M$75,1,Podatki!$I$4:$I$75,4)^3-COUNTIFS(Podatki!$B$4:$B$75,"B",Podatki!$M$4:$M$75,1,Podatki!$I$4:$I$75,4) -> 0 | C29: =COUNTIFS(Podatki!$B$4:$B$75,"B",Podatki!$M$4:$M$75,1,Podatki!$J$4:$J$75,4)^3-COUNTIFS(Podatki!$B$4:$B$75,"B",Podatki!$M$4:$M$75,1,Podatki!$J$4:$J$75,4) -> 0 | D29: =COUNTIFS(Podatki!$B$4:$B$75,"B",Podatki!$M$4:$M$75,1,Podatki!$K$4:$K$75,4)^3-COUNTIFS(Podatki!$B$4:$B$75,"B",Podatki!$M$4:$M$75,1,Podatki!$K$4:$K$75,4) -> 60
A30: ΣT | B30: =SUM(B25:D29) -> 96
A31: W | B31: =IF(B20<2,"",12*B22/(9*(B20^3-B20)-3*B30)) -> 0.49438202
A34: Prototip C – Uizard
A35: n (število težav) | B35: =COUNTIFS(Podatki!$B$4:$B$75,"C",Podatki!$M$4:$M$75,1) -> 36
A36: Povprečna vsota rangov | B36: =3*(B35+1)/2 -> 55.5
A37: S | B37: =SUMPRODUCT((Podatki!$B$4:$B$75="C")*(Podatki!$M$4:$M$75=1)*(Podatki!$Q$4:$Q$75-B36)^2) -> 11228
A38: Popravek za vezi, t³ − t po oceni in ocenjevalcu
A39: Ocena | B39: Ocenjevalec 1 | C39: Ocenjevalec 2 | D39: Ocenjevalec 3
A40: 0 | B40: =COUNTIFS(Podatki!$B$4:$B$75,"C",Podatki!$M$4:$M$75,1,Podatki!$I$4:$I$75,0)^3-COUNTIFS(Podatki!$B$4:$B$75,"C",Podatki!$M$4:$M$75,1,Podatki!$I$4:$I$75,0) -> 0 | C40: =COUNTIFS(Podatki!$B$4:$B$75,"C",Podatki!$M$4:$M$75,1,Podatki!$J$4:$J$75,0)^3-COUNTIFS(Podatki!$B$4:$B$75,"C",Podatki!$M$4:$M$75,1,Podatki!$J$4:$J$75,0) -> 0 | D40: =COUNTIFS(Podatki!$B$4:$B$75,"C",Podatki!$M$4:$M$75,1,Podatki!$K$4:$K$75,0)^3-COUNTIFS(Podatki!$B$4:$B$75,"C",Podatki!$M$4:$M$75,1,Podatki!$K$4:$K$75,0) -> 0
A41: 1 | B41: =COUNTIFS(Podatki!$B$4:$B$75,"C",Podatki!$M$4:$M$75,1,Podatki!$I$4:$I$75,1)^3-COUNTIFS(Podatki!$B$4:$B$75,"C",Podatki!$M$4:$M$75,1,Podatki!$I$4:$I$75,1) -> 0 | C41: =COUNTIFS(Podatki!$B$4:$B$75,"C",Podatki!$M$4:$M$75,1,Podatki!$J$4:$J$75,1)^3-COUNTIFS(Podatki!$B$4:$B$75,"C",Podatki!$M$4:$M$75,1,Podatki!$J$4:$J$75,1) -> 0 | D41: =COUNTIFS(Podatki!$B$4:$B$75,"C",Podatki!$M$4:$M$75,1,Podatki!$K$4:$K$75,1)^3-COUNTIFS(Podatki!$B$4:$B$75,"C",Podatki!$M$4:$M$75,1,Podatki!$K$4:$K$75,1) -> 504
A42: 2 | B42: =COUNTIFS(Podatki!$B$4:$B$75,"C",Podatki!$M$4:$M$75,1,Podatki!$I$4:$I$75,2)^3-COUNTIFS(Podatki!$B$4:$B$75,"C",Podatki!$M$4:$M$75,1,Podatki!$I$4:$I$75,2) -> 6 | C42: =COUNTIFS(Podatki!$B$4:$B$75,"C",Podatki!$M$4:$M$75,1,Podatki!$J$4:$J$75,2)^3-COUNTIFS(Podatki!$B$4:$B$75,"C",Podatki!$M$4:$M$75,1,Podatki!$J$4:$J$75,2) -> 24 | D42: =COUNTIFS(Podatki!$B$4:$B$75,"C",Podatki!$M$4:$M$75,1,Podatki!$K$4:$K$75,2)^3-COUNTIFS(Podatki!$B$4:$B$75,"C",Podatki!$M$4:$M$75,1,Podatki!$K$4:$K$75,2) -> 210
A43: 3 | B43: =COUNTIFS(Podatki!$B$4:$B$75,"C",Podatki!$M$4:$M$75,1,Podatki!$I$4:$I$75,3)^3-COUNTIFS(Podatki!$B$4:$B$75,"C",Podatki!$M$4:$M$75,1,Podatki!$I$4:$I$75,3) -> 3360 | C43: =COUNTIFS(Podatki!$B$4:$B$75,"C",Podatki!$M$4:$M$75,1,Podatki!$J$4:$J$75,3)^3-COUNTIFS(Podatki!$B$4:$B$75,"C",Podatki!$M$4:$M$75,1,Podatki!$J$4:$J$75,3) -> 5814 | D43: =COUNTIFS(Podatki!$B$4:$B$75,"C",Podatki!$M$4:$M$75,1,Podatki!$K$4:$K$75,3)^3-COUNTIFS(Podatki!$B$4:$B$75,"C",Podatki!$M$4:$M$75,1,Podatki!$K$4:$K$75,3) -> 2184
A44: 4 | B44: =COUNTIFS(Podatki!$B$4:$B$75,"C",Podatki!$M$4:$M$75,1,Podatki!$I$4:$I$75,4)^3-COUNTIFS(Podatki!$B$4:$B$75,"C",Podatki!$M$4:$M$75,1,Podatki!$I$4:$I$75,4) -> 6840 | C44: =COUNTIFS(Podatki!$B$4:$B$75,"C",Podatki!$M$4:$M$75,1,Podatki!$J$4:$J$75,4)^3-COUNTIFS(Podatki!$B$4:$B$75,"C",Podatki!$M$4:$M$75,1,Podatki!$J$4:$J$75,4) -> 3360 | D44: =COUNTIFS(Podatki!$B$4:$B$75,"C",Podatki!$M$4:$M$75,1,Podatki!$K$4:$K$75,4)^3-COUNTIFS(Podatki!$B$4:$B$75,"C",Podatki!$M$4:$M$75,1,Podatki!$K$4:$K$75,4) -> 720
A45: ΣT | B45: =SUM(B40:D44) -> 23022
...

Sheet Kontrolno vprašanje
A1: Kateri prototip je bil po mnenju ocenjevalca izdelan ročno? Pravilni odgovor je B.
A3: Ocenjevalec | B3: Odgovor | C3: Pravilno | D3: Utemeljitev
A4: 1 | B4: B | C4: =IF(B4="B","da","ne") -> da | D4: Izdelan je konsistentno skozi vse strani
A5: 2 | B5: B | C5: =IF(B5="B","da","ne") -> da | D5: Prototip B je najbolj estetsko in funkcionalno dodelan. Odločal sem se med prototipoma B in D, ki sta za razliko od drugih dveh precej izpopolnjena. A na koncu je prevladal prototip B, saj pri zaslonski tipkovnici ne vsebuje tujih črk (Q, X, Y, W, ...), ki jih za iskanje slovenske besede tako ali tako ne bi potrebovali. Taka stopnja detajlov loči ročno delo od umetne inteligence.
A6: 3 | B6: C | C6: =IF(B6="B","da","ne") -> ne | D6: Najmanj kompliciran način izdelave; napake, ki so običajne pri ročni izdelavi
A8: 2 pravilna odgovora od 3.

Sheet Grafi
A3: Število odkritih težav po prototipih
A4: Kategorija | B4: Vrednost
A5: A – Visily | B5: =Analiza!C30 -> 21
A6: B – Ročni | B6: =Analiza!D30 -> 6
A7: C – Uizard | B7: =Analiza!E30 -> 36
A8: D – Figma Make | B8: =Analiza!F30 -> 9
A10: Skupna ocena prototipa
A11: Kategorija | B11: Vrednost
A12: A – Visily | B12: =Analiza!C15 -> 18.333333
A13: B – Ročni | B13: =Analiza!D15 -> 13.666667
A14: C – Uizard | B14: =Analiza!E15 -> 21.333333
A15: D – Figma Make | B15: =Analiza!F15 -> 13
A17: Število odkritih težav po hevristikah
A18: Kategorija | B18: Vrednost
A19: 1. Vidnost stanja sistema | B19: =Analiza!G20 -> 16
A20: 2. Ujemanje sistema z resničnim svetom | B20: =Analiza!G21 -> 13
A21: 3. Nadzor in svoboda uporabnika | B21: =Analiza!G22 -> 4
A22: 4. Konsistentnost in standardi | B22: =Analiza!G23 -> 21
A23: 5. Preprečevanje napak (izključena) | B23: =Analiza!G24 -> 1
A24: 6. Prepoznavanje namesto pomnjenja | B24: =Analiza!G25 -> 3
A25: 7. Prilagodljivost in učinkovitost uporabe (izključena) | B25: =Analiza!G26 -> 0
A26: 8. Estetsko in minimalistično oblikovanje | B26: =Analiza!G27 -> 11
A27: 9. Pomoč pri prepoznavanju in odpravljanju napak | B27: =Analiza!G28 -> 0
A28: 10. Pomoč in dokumentacija | B28: =Analiza!G29 -> 3
